<?xml version="1.0"?>
<!-- ros2 launch limo_description display.launch.py model:=urdf/visual.urdf -->
<!-- ros2 topic list -t -->
<!-- ros2 interface show tf2_msgs/msg/TFMessage -->
<!-- ros2 topic echo /tf_static -->
<!-- ros2 topic echo /tf -->

<!-- /colcon_ws/src/limo_description/urdf >> check_urdf visual.urdf -->
<robot name="myfirst">
    <material name="white">
        <color rgba="1 1 1 1" />
    </material>
    <material name="blue">
        <color rgba="0 0 0.8 1" />
    </material>
    <material name="black">
        <color rgba="0 0 0 1" />
    </material>

    <link name="base_link"><!-- tf 이름 -->
        <visual>
            <geometry>
                <cylinder length="0.6" radius="0.2" />
            </geometry>
            <material name="blue" />
        </visual>
    </link>

    <link name="right_leg">
        <visual>
            <geometry>
                <box size="0.6 0.1 0.2" />
            </geometry>
            <origin rpy="0 1.57 0" xyz="0 0 -0.3" />
            <material name="white" />
        </visual>
    </link>
    <joint name="base_to_right_leg" type="fixed">
        <parent link="base_link" />
        <child link="right_leg" />
        <origin xyz="0 -0.22 0.25" />
    </joint>

    <link name="right_front_wheel">
        <visual>
            <geometry>
                <cylinder length="0.1" radius="0.035" />
            </geometry>
            <origin rpy="1.57 0 0" xyz="0 0 0" />
            <material name="black" />
        </visual>
    </link>
    <joint name="right_front_wheel_joint" type="continuous">
        <axis rpy="0 0 0" xyz="0 1 0" />
        <parent link="right_leg" />
        <child link="right_front_wheel" />
        <origin xyz="0 0 -0.63" />
    </joint>
    
    <link name="left_leg">
        <visual>
            <geometry>
                <box size="0.6 0.1 0.2" />
            </geometry>
            <origin rpy="0 1.57 0" xyz="0 0 -0.3" />
            <material name="white" />
        </visual>
    </link>

    <joint name="base_to_left_leg" type="fixed">
        <parent link="base_link" />
        <child link="left_leg" />
        <origin xyz="0 0.22 0.25" />
    </joint>


    <link name="left_front_wheel">
        <visual>
            <geometry>
                <cylinder length="0.1" radius="0.035" />
            </geometry>
            <origin rpy="-1.57 0 0" xyz="0 0 0" />
            <material name="black" />
        </visual>
    </link>
    <joint name="left_front_wheel_joint" type="continuous">
        <axis rpy="0 0 0" xyz="0 1 0" />
        <parent link="left_leg" />
        <child link="left_front_wheel" />
        <origin xyz="0 0 -0.63" />
    </joint>
</robot>